Workbook

Sheet Assumptions
A1: Входные параметры (Assumptions)
A3: 1. Финансирование и Стартовые активы
A4: Начальный капитал (собственный) | B4: 24000 | C4: EUR
A5: Ремонт и отделка помещения (PP&E) | B5: 8000 | C5: EUR
A6: Профессиональное б/у оборудование (PP&E) | B6: 3500 | C6: EUR
A7: Мебель (PP&E) | B7: 3000 | C7: EUR
A8: Депозит за аренду (долгосрочный актив) | B8: 1200 | C8: EUR
A9: Первоначальный товарный запас (оборотный актив) | B9: 2000 | C9: EUR
A10: Разовые расходы на открытие (юристы, APR, маркетинг) | B10: 1700 | C10: EUR
A11: 2. Аренда и Операционные расходы в месяц
A12: Аренда помещения (40 кв.м.) | B12: 600 | C12: EUR
A13: Коммунальные услуги | B13: 300 | C13: EUR
A14: Количество сотрудников | B14: 2 | C14: чел
A15: Зарплата 1 сотрудника (нетто) | B15: 550 | C15: EUR
A16: Налог на зарплату (соцотчисления сверх нетто) | B16: 0.6 | C16: %
A17: Бухгалтерия и ПО | B17: 150 | C17: EUR
A18: Прочие расходы (лицензии Sokoj/OFPS, хозтовары) | B18: 150 | C18: EUR
A19: 3. Продажи и Себестоимость
A20: Курс EUR / RSD | B20: 117 | C20: RSD
A21: Средний чек | B21: 300 | C21: RSD
A22: Количество гостей в день (steady state) | B22: 100 | C22: чел
A23: Рабочих дней в месяце | B23: 30 | C23: дней
A24: Себестоимость продуктов (COGS %) | B24: 0.25 | C24: %
A25: Налог на прибыль в Сербии | B25: 0.15 | C25: %
A26: Срок полезного использования PP&E | B26: 60 | C26: мес.
A27: 4. Темп выхода на мощность (Ramp-up)
A28: Месяц 1 | B28: 0.5 | C28: %
A29: Месяц 2 | B29: 0.7 | C29: %
A30: Месяц 3 | B30: 0.85 | C30: %
A31: Месяцы 4-12 | B31: 1 | C31: %

Sheet Model
A1: Интегрированная 3-Statement модель
A2: Статья | B2: Ед. | C2: М0 (Старт) | D2: М1 | E2: М2 | F2: М3 | G2: М4 | H2: М5 | I2: М6 | J2: М7 | K2: М8 | L2: М9 | M2: М10 | N2: М11 | O2: М12 | P2: Итого Y1
A3: 1. РАБОЧИЕ ПОКАЗАТЕЛИ
A4: Коэффициент Ramp-up | C4: 0 | D4: =Assumptions!$B$28 | E4: =Assumptions!$B$29 | F4: =Assumptions!$B$30 | G4: =Assumptions!$B$31 | H4: =Assumptions!$B$31 | I4: =Assumptions!$B$31 | J4: =Assumptions!$B$31 | K4: =Assumptions!$B$31 | L4: =Assumptions!$B$31 | M4: =Assumptions!$B$31 | N4: =Assumptions!$B$31 | O4: =Assumptions!$B$31 | P4: -
A5: Количество гостей в день | C5: =Assumptions!$B$22*C4 | D5: =Assumptions!$B$22*D4 | E5: =Assumptions!$B$22*E4 | F5: =Assumptions!$B$22*F4 | G5: =Assumptions!$B$22*G4 | H5: =Assumptions!$B$22*H4 | I5: =Assumptions!$B$22*I4 | J5: =Assumptions!$B$22*J4 | ... O5: =Assumptions!$B$22*O4 | P5: =AVERAGE(D5:O5)
A6: Средний чек (в EUR) | C6: =Assumptions!$B$21/Assumptions!$B$20 | D6: =Assumptions!$B$21/Assumptions!$B$20 | E6: =Assumptions!$B$21/Assumptions!$B$20 | F6: =Assumptions!$B$21/Assumptions!$B$20 | G6: =Assumptions!$B$21/Assumptions!$B$20 | H6: =Assumptions!$B$21/Assumptions!$B$20 | I6: =Assumptions!$B$21/Assumptions!$B$20 | J6: =Assumptions!$B$21/Assumptions!$B$20 | ... O6: =Assumptions!$B$21/Assumptions!$B$20 | P6: =AVERAGE(D6:O6)
A7: 2. ОТЧЕТ О ПРИБЫЛЯХ И УБЫТКАХ (Income Statement)
A8: Выручка | C8: 0 | D8: =D5*D6*Assumptions!$B$23 | E8: =E5*E6*Assumptions!$B$23 | F8: =F5*F6*Assumptions!$B$23 | G8: =G5*G6*Assumptions!$B$23 | H8: =H5*H6*Assumptions!$B$23 | I8: =I5*I6*Assumptions!$B$23 | J8: =J5*J6*Assumptions!$B$23 | K8: =K5*K6*Assumptions!$B$23 | ... O8: =O5*O6*Assumptions!$B$23 | P8: =SUM(D8:O8)
A9: Себестоимость (COGS) | C9: 0 | D9: =-D8*Assumptions!$B$24 | E9: =-E8*Assumptions!$B$24 | F9: =-F8*Assumptions!$B$24 | G9: =-G8*Assumptions!$B$24 | H9: =-H8*Assumptions!$B$24 | I9: =-I8*Assumptions!$B$24 | J9: =-J8*Assumptions!$B$24 | K9: =-K8*Assumptions!$B$24 | ... O9: =-O8*Assumptions!$B$24 | P9: =SUM(D9:O9)
A10: Валовая прибыль (Gross Profit) | C10: 0 | D10: =D8+D9 | E10: =E8+E9 | F10: =F8+F9 | G10: =G8+G9 | H10: =H8+H9 | I10: =I8+I9 | J10: =J8+J9 | K10: =K8+K9 | ... O10: =O8+O9 | P10: =SUM(D10:O10)
A11: Аренда помещения | C11: 0 | D11: =-Assumptions!$B$12 | E11: =-Assumptions!$B$12 | F11: =-Assumptions!$B$12 | G11: =-Assumptions!$B$12 | H11: =-Assumptions!$B$12 | I11: =-Assumptions!$B$12 | J11: =-Assumptions!$B$12 | K11: =-Assumptions!$B$12 | ... O11: =-Assumptions!$B$12 | P11: =SUM(D11:O11)
A12: Коммунальные услуги | C12: 0 | D12: =-Assumptions!$B$13 | E12: =-Assumptions!$B$13 | F12: =-Assumptions!$B$13 | G12: =-Assumptions!$B$13 | H12: =-Assumptions!$B$13 | I12: =-Assumptions!$B$13 | J12: =-Assumptions!$B$13 | K12: =-Assumptions!$B$13 | ... O12: =-Assumptions!$B$13 | P12: =SUM(D12:O12)
A13: ФОТ сотрудников с налогами | C13: 0 | D13: =-Assumptions!$B$14*Assumptions!$B$15*(1+Assumptions!$B$16) | E13: =-Assumptions!$B$14*Assumptions!$B$15*(1+Assumptions!$B$16) | F13: =-Assumptions!$B$14*Assumptions!$B$15*(1+Assumptions!$B$16) | G13: =-Assumptions!$B$14*Assumptions!$B$15*(1+Assumptions!$B$16) | H13: =-Assumptions!$B$14*Assumptions!$B$15*(1+Assumptions!$B$16) | I13: =-Assumptions!$B$14*Assumptions!$B$15*(1+Assumptions!$B$16) | J13: =-Assumptions!$B$14*Assumptions!$B$15*(1+Assumptions!$B$16) | K13: =-Assumptions!$B$14*Assumptions!$B$15*(1+Assumptions!$B$16) | ... O13: =-Assumptions!$B$14*Assumptions!$B$15*(1+Assumptions!$B$16) | P13: =SUM(D13:O13)
A14: Бухгалтерия и ПО | C14: 0 | D14: =-Assumptions!$B$17 | E14: =-Assumptions!$B$17 | F14: =-Assumptions!$B$17 | G14: =-Assumptions!$B$17 | H14: =-Assumptions!$B$17 | I14: =-Assumptions!$B$17 | J14: =-Assumptions!$B$17 | K14: =-Assumptions!$B$17 | ... O14: =-Assumptions!$B$17 | P14: =SUM(D14:O14)
A15: Прочие расходы (лицензии, расходники) | C15: 0 | D15: =-Assumptions!$B$18 | E15: =-Assumptions!$B$18 | F15: =-Assumptions!$B$18 | G15: =-Assumptions!$B$18 | H15: =-Assumptions!$B$18 | I15: =-Assumptions!$B$18 | J15: =-Assumptions!$B$18 | K15: =-Assumptions!$B$18 | ... O15: =-Assumptions!$B$18 | P15: =SUM(D15:O15)
A16: EBITDA | C16: 0 | D16: =D10+SUM(D11:D15) | E16: =E10+SUM(E11:E15) | F16: =F10+SUM(F11:F15) | G16: =G10+SUM(G11:G15) | H16: =H10+SUM(H11:H15) | I16: =I10+SUM(I11:I15) | J16: =J10+SUM(J11:J15) | K16: =K10+SUM(K11:K15) | ... O16: =O10+SUM(O11:O15) | P16: =SUM(D16:O16)
A17: Амортизация (D&A) | C17: 0 | D17: =-(Assumptions!$B$5+Assumptions!$B$6+Assumptions!$B$7)/Assumptions!$B$26 | E17: =-(Assumptions!$B$5+Assumptions!$B$6+Assumptions!$B$7)/Assumptions!$B$26 | F17: =-(Assumptions!$B$5+Assumptions!$B$6+Assumptions!$B$7)/Assumptions!$B$26 | G17: =-(Assumptions!$B$5+Assumptions!$B$6+Assumptions!$B$7)/Assumptions!$B$26 | H17: =-(Assumptions!$B$5+Assumptions!$B$6+Assumptions!$B$7)/Assumptions!$B$26 | I17: =-(Assumptions!$B$5+Assumptions!$B$6+Assumptions!$B$7)/Assumptions!$B$26 | J17: =-(Assumptions!$B$5+Assumptions!$B$6+Assumptions!$B$7)/Assumptions!$B$26 | K17: =-(Assumptions!$B$5+Assumptions!$B$6+Assumptions!$B$7)/Assumptions!$B$26 | ... O17: =-(Assumptions!$B$5+Assumptions!$B$6+Assumptions!$B$7)/Assumptions!$B$26 | P17: =SUM(D17:O17)
A18: Операционная прибыль (EBIT) | C18: 0 | D18: =D16+D17 | E18: =E16+E17 | F18: =F16+F17 | G18: =G16+G17 | H18: =H16+H17 | I18: =I16+I17 | J18: =J16+J17 | K18: =K16+K17 | ... O18: =O16+O17 | P18: =SUM(D18:O18)
A19: Налог на прибыль | C19: 0 | D19: =IF(D18>0, -D18*Assumptions!$B$25, 0) | E19: =IF(E18>0, -E18*Assumptions!$B$25, 0) | F19: =IF(F18>0, -F18*Assumptions!$B$25, 0) | G19: =IF(G18>0, -G18*Assumptions!$B$25, 0) | H19: =IF(H18>0, -H18*Assumptions!$B$25, 0) | I19: =IF(I18>0, -I18*Assumptions!$B$25, 0) | J19: =IF(J18>0, -J18*Assumptions!$B$25, 0) | K19: =IF(K18>0, -K18*Assumptions!$B$25, 0) | ... O19: =IF(O18>0, -O18*Assumptions!$B$25, 0) | P19: =SUM(D19:O19)
A20: Чистая прибыль | C20: =-Assumptions!$B$10 | D20: =D18+D19 | E20: =E18+E19 | F20: =F18+F19 | G20: =G18+G19 | H20: =H18+H19 | I20: =I18+I19 | J20: =J18+J19 | K20: =K18+K19 | ... O20: =O18+O19 | P20: =SUM(C20:O20)
A21: 3.БАЛАНСОВЫЙ ОТЧЕТ (Balance Sheet)
A22: Денежные средства (Cash) | C22: =Assumptions!$B$4-(Assumptions!$B$5+Assumptions!$B$6+Assumptions!$B$7)-Assumptions!$B$8-Assumptions!$B$12-Assumptions!$B$9-Assumptions!$B$10 | D22: =D44 | E22: =E44 | F22: =F44 | G22: =G44 | H22: =H44 | I22: =I44 | J22: =J44 | K22: =K44 | ... O22: =O44 | P22: =O22
A23: Товарный запас (Inventory) | C23: =Assumptions!$B$9 | D23: =C23 | E23: =D23 | F23: =E23 | G23: =F23 | H23: =G23 | I23: =H23 | J23: =I23 | K23: =J23 | ... P23: =O23
A24: Депозит за аренду (Deposit) | C24: =Assumptions!$B$8 | D24: =C24 | E24: =D24 | F24: =E24 | G24: =F24 | H24: =G24 | I24: =H24 | J24: =I24 | K24: =J24 | ... P24: =O24
A25: Предоплата по аренде | C25: =Assumptions!$B$12 | D25: 0 | E25: 0 | F25: 0 | G25: 0 | H25: 0 | I25: 0 | J25: 0 | K25: 0 | L25: 0 | M25: 0 | N25: 0 | O25: 0 | P25: =O25
A26: Основные средства (PP&E net) | C26: =Assumptions!$B$5+Assumptions!$B$6+Assumptions!$B$7 | D26: =C26+D17 | E26: =D26+E17 | F26: =E26+F17 | G26: =F26+G17 | H26: =G26+H17 | I26: =H26+I17 | J26: =I26+J17 | K26: =J26+K17 | ... O26: =N26+O17 | P26: =O26
A27: ИТОГО АКТИВЫ | C27: =SUM(C22:C26) | D27: =SUM(D22:D26) | E27: =SUM(E22:E26) | F27: =SUM(F22:F26) | G27: =SUM(G22:G26) | H27: =SUM(H22:H26) | I27: =SUM(I22:I26) | J27: =SUM(J22:J26) | ... O27: =SUM(O22:O26) | P27: =O27
A28: Собственный капитал | C28: =Assumptions!$B$4 | D28: =C28 | E28: =D28 | F28: =E28 | G28: =F28 | H28: =G28 | I28: =H28 | J28: =I28 | K28: =J28 | ... P28: =O28
A29: Нераспределенная прибыль (RE) | C29: =C20 | D29: =C29+D20 | E29: =D29+E20 | F29: =E29+F20 | G29: =F29+G20 | H29: =G29+H20 | I29: =H29+I20 | J29: =I29+J20 | K29: =J29+K20 | ... O29: =N29+O20 | P29: =O29
A30: ИТОГО ПАССИВЫ + КАПИТАЛ | C30: =C28+C29 | D30: =D28+D29 | E30: =E28+E29 | F30: =F28+F29 | G30: =G28+G29 | H30: =H28+H29 | I30: =I28+I29 | J30: =J28+J29 | ... O30: =O28+O29 | P30: =O30
A31: Балансовая проверка (Asset - L&E) | C31: =C27-C30 | D31: =D27-D30 | E31: =E27-E30 | F31: =F27-F30 | G31: =G27-G30 | H31: =H27-H30 | I31: =I27-I30 | J31: =J27-J30 | ... O31: =O27-O30 | P31: =O31
A32: 4. ОТЧЕТ О ДВИЖЕНИИ ДЕНЕЖНЫХ СРЕДСТВ (Cash Flow Statement)
A33: Чистая прибыль (Net Income) | C33: =C20 | D33: =D20 | E33: =E20 | F33: =F20 | G33: =G20 | H33: =H20 | I33: =I20 | J33: =J20 | ... O33: =O20 | P33: =SUM(C33:O33)
A34: Корректировка: Амортизация (D&A) | C34: 0 | D34: =-D17 | E34: =-E17 | F34: =-F17 | G34: =-G17 | H34: =-H17 | I34: =-I17 | J34: =-J17 | K34: =-K17 | ... O34: =-O17 | P34: =SUM(D34:O34)
A35: Изменение оборотного капитала | C35: 0 | D35: =C25-D25 | E35: 0 | F35: 0 | G35: 0 | H35: 0 | I35: 0 | J35: 0 | K35: 0 | L35: 0 | M35: 0 | N35: 0 | O35: 0 | P35: =SUM(D35:O35)
A36: Денежный поток от опер. деятельности (CFO) | C36: =SUM(C33:C35) | D36: =SUM(D33:D35) | E36: =SUM(E33:E35) | F36: =SUM(F33:F35) | G36: =SUM(G33:G35) | H36: =SUM(H33:H35) | I36: =SUM(I33:I35) | J36: =SUM(J33:J35) | ... O36: =SUM(O33:O35) | P36: =SUM(C36:O36)
A37: Капитальные затраты (CapEx) | C37: =-(Assumptions!$B$5+Assumptions!$B$6+Assumptions!$B$7) | D37: 0 | E37: 0 | F37: 0 | G37: 0 | H37: 0 | I37: 0 | J37: 0 | K37: 0 | L37: 0 | M37: 0 | N37: 0 | O37: 0 | P37: =SUM(C37:O37)
A38: Депозиты и предоплаты | C38: =-(Assumptions!$B$8+Assumptions!$B$12+Assumptions!$B$9) | D38: 0 | E38: 0 | F38: 0 | G38: 0 | H38: 0 | I38: 0 | J38: 0 | K38: 0 | L38: 0 | M38: 0 | N38: 0 | O38: 0 | P38: =SUM(C38:O38)
A39: Денежный поток от инвест. деятельности (CFI) | C39: =C37+C38 | D39: 0 | E39: 0 | F39: 0 | G39: 0 | H39: 0 | I39: 0 | J39: 0 | K39: 0 | L39: 0 | M39: 0 | N39: 0 | O39: 0 | P39: =SUM(C39:O39)
A40: Привлечение собственного капитала | C40: =Assumptions!$B$4 | D40: 0 | E40: 0 | F40: 0 | G40: 0 | H40: 0 | I40: 0 | J40: 0 | K40: 0 | L40: 0 | M40: 0 | N40: 0 | O40: 0 | P40: =SUM(C40:O40)
...
